<?xml version="1.0" ?>
<robot name="dabomb" xmlns:xacro="http://www.ros.org/wiki/xacro">

<material name="gray">
  <color rgba="0.75 0.75 0.75 1.0"/>  <!-- This is gray with full opacity -->
</material>


<xacro:include filename="$(find dabomb_description)/urdf/materials.xacro" />
<xacro:include filename="$(find dabomb_description)/urdf/dabomb.trans" />
<xacro:include filename="$(find dabomb_description)/urdf/dabomb.gazebo" />
<link name="base_footprint" />

<link name="base_link">
  <inertial>
    <origin xyz="0.001965778230803289 0.00012164122075361151 0.06076837613584456" rpy="0 0 0"/>
    <mass value="3.2995710672768235"/>
    <inertia ixx="0.032808" iyy="0.061307" izz="0.086932" ixy="-3.2e-05" iyz="-8e-06" ixz="-8.9e-05"/>
  </inertial>
  <visual>
    <origin xyz="0 0 -0.04" rpy="0 0 0"/>
    <geometry>
      <mesh filename="file://$(find dabomb_description)/meshes/base_link.stl" scale="0.001 0.001 0.001"/>
    </geometry>
    <material name="gray"/>
  </visual>
  <collision>
    <origin xyz="0 0 -0.04" rpy="0 0 0"/>
    <geometry>
      <mesh filename="file://$(find dabomb_description)/meshes/base_link.stl" scale="0.001 0.001 0.001"/>
    </geometry>
  </collision>
</link>

<link name="Wheel1_1">
  <inertial>
    <origin xyz="3.605747672386084e-07 0.00934999998147884 -8.583050173371909e-10" rpy="0 0 0"/>
    <mass value="0.7357403909763499"/>
    <inertia ixx="0.000317" iyy="0.00059" izz="0.000317" ixy="-0.0" iyz="0.0" ixz="0.0"/>
  </inertial>
  <visual>
    <origin xyz="-0.15 -0.15 -0.04" rpy="0 0 0"/>
    <geometry>
      <mesh filename="file://$(find dabomb_description)/meshes/Wheel1_1.stl" scale="0.001 0.001 0.001"/>
    </geometry>
    <material name="gray"/>
  </visual>
  <collision>
    <origin xyz="-0.15 -0.15 -0.04" rpy="0 0 0"/>
    <geometry>
      <mesh filename="file://$(find dabomb_description)/meshes/Wheel1_1.stl" scale="0.001 0.001 0.001"/>
    </geometry>
  </collision>
</link>

<link name="Wheel3_1">
  <inertial>
    <origin xyz="-3.6057476762718643e-07 0.00934999998147884 -8.583049965205092e-10" rpy="0 0 0"/>
    <mass value="0.7357403909763499"/>
    <inertia ixx="0.000317" iyy="0.00059" izz="0.000317" ixy="-0.0" iyz="0.0" ixz="0.0"/>
  </inertial>
  <visual>
    <origin xyz="0.15 -0.15 -0.04" rpy="0 0 0"/>
    <geometry>
      <mesh filename="file://$(find dabomb_description)/meshes/Wheel3_1.stl" scale="0.001 0.001 0.001"/>
    </geometry>
    <material name="gray"/>
  </visual>
  <collision>
    <origin xyz="0.15 -0.15 -0.04" rpy="0 0 0"/>
    <geometry>
      <mesh filename="file://$(find dabomb_description)/meshes/Wheel3_1.stl" scale="0.001 0.001 0.001"/>
    </geometry>
  </collision>
</link>

<link name="Wheel2_1">
  <inertial>
    <origin xyz="3.605747672386084e-07 -0.00934999998147884 -8.583056140820666e-10" rpy="0 0 0"/>
    <mass value="0.7357403909763499"/>
    <inertia ixx="0.000317" iyy="0.00059" izz="0.000317" ixy="0.0" iyz="-0.0" ixz="-0.0"/>
  </inertial>
  <visual>
    <origin xyz="-0.15 0.15 -0.04" rpy="0 0 0"/>
    <geometry>
      <mesh filename="file://$(find dabomb_description)/meshes/Wheel2_1.stl" scale="0.001 0.001 0.001"/>
    </geometry>
    <material name="gray"/>
  </visual>
  <collision>
    <origin xyz="-0.15 0.15 -0.04" rpy="0 0 0"/>
    <geometry>
      <mesh filename="file://$(find dabomb_description)/meshes/Wheel2_1.stl" scale="0.001 0.001 0.001"/>
    </geometry>
  </collision>
</link>

<link name="Wheel4_1">
  <inertial>
    <origin xyz="-3.6057476762718643e-07 -0.00934999998147884 -8.583055516320215e-10" rpy="0 0 0"/>
    <mass value="0.7357403909763499"/>
    <inertia ixx="0.000317" iyy="0.00059" izz="0.000317" ixy="0.0" iyz="-0.0" ixz="-0.0"/>
  </inertial>
  <visual>
    <origin xyz="0.15 0.15 -0.04" rpy="0 0 0"/>
    <geometry>
      <mesh filename="file://$(find dabomb_description)/meshes/Wheel4_1.stl" scale="0.001 0.001 0.001"/>
    </geometry>
    <material name="gray"/>
  </visual>
  <collision>
    <origin xyz="0.15 0.15 -0.04" rpy="0 0 0"/>
    <geometry>
      <mesh filename="file://$(find dabomb_description)/meshes/Wheel4_1.stl" scale="0.001 0.001 0.001"/>
    </geometry>
  </collision>
</link>

<link name="laser">
  <inertial>
    <origin xyz="0.0039907248324316845 -0.00022724344297910342 -0.002459373991692604" rpy="0 0 0"/>
    <mass value="0.2649835736448253"/>
    <inertia ixx="8.2e-05" iyy="8.5e-05" izz="0.000145" ixy="-0.0" iyz="0.0" ixz="-2e-06"/>
  </inertial>
  <visual>
    <origin xyz="0.0 -0.0 -0.19" rpy="0 0 0"/>
    <geometry>
      <mesh filename="file://$(find dabomb_description)/meshes/LIDAR_1.stl" scale="0.001 0.001 0.001"/>
    </geometry>
    <material name="gray"/>
  </visual>
  <collision>
    <origin xyz="0.0 -0.0 -0.19" rpy="0 0 0"/>
    <geometry>
      <mesh filename="file://$(find dabomb_description)/meshes/LIDAR_1.stl" scale="0.001 0.001 0.001"/>
    </geometry>
  </collision>
</link>

<joint name="base_joint" type="fixed">
  <origin xyz="0.0 0.0 0.04" rpy="0 0 0"/>
  <parent link="base_footprint"/>
  <child link="base_link"/>
</joint>

<joint name="Wheel1" type="continuous">
  <origin xyz="0.15 0.15 0.0" rpy="0 0 0"/>
  <parent link="base_link"/>
  <child link="Wheel1_1"/>
  <axis xyz="-0.0 1.0 0.0"/>
</joint>

<joint name="Wheel3" type="continuous">
  <origin xyz="-0.15 0.15 0.0" rpy="0 0 0"/>
  <parent link="base_link"/>
  <child link="Wheel3_1"/>
  <axis xyz="0.0 1.0 0.0"/>
</joint>

<joint name="Wheel2" type="continuous">
  <origin xyz="0.15 -0.15 0.0" rpy="0 0 0"/>
  <parent link="base_link"/>
  <child link="Wheel2_1"/>
  <axis xyz="-0.0 -1.0 0.0"/>
</joint>

<joint name="Wheel4" type="continuous">
  <origin xyz="-0.15 -0.15 0.0" rpy="0 0 0"/>
  <parent link="base_link"/>
  <child link="Wheel4_1"/>
  <axis xyz="0.0 -1.0 0.0"/>
</joint>

<joint name="laser_joint" type="fixed">
  <origin xyz="0.0 0.0 0.15" rpy="0 0 ${pi}"/>
  <parent link="base_link"/>
  <child link="laser"/>
</joint>

</robot>
